2023-10-15 10:25:00,862 - DEBUG - Using proactor: IocpProactor
2023-10-15 10:25:00,864 - INFO - Ultra96 starting...
2023-10-15 10:25:08,026 - INFO - Relay Node server starting:
2023-10-15 10:25:08,610 - INFO - Connected to eval_server at 127.0.0.1:50828.
2023-10-15 10:25:08,610 - INFO - EvalClient: Sent handshake.
2023-10-15 10:25:08,612 - INFO - Relay Node server listening on 0.0.0.0:8080
2023-10-15 10:25:08,803 - INFO - Visualizer Client: CONNACK received with code 0.
2023-10-15 10:25:08,987 - INFO - Subscribed topic: test
2023-10-15 10:25:15,529 - INFO - Stopping Ultra96...
2023-10-15 10:25:15,530 - INFO - Eval Client stopped.
2023-10-15 10:25:15,531 - ERROR - unhandled exception during asyncio.run() shutdown
task: <Task finished name='Task-1' coro=<main() done, defined at C:\Users\Alwin Ang\OneDrive - National University of Singapore\Y4S1\CG4002\CG4002_capstone\external_communications\Ultra96\main.py:167> exception=TypeError('An asyncio.Future, a coroutine or an awaitable is required')>
Traceback (most recent call last):
  File "C:\Users\Alwin Ang\AppData\Local\Programs\Python\Python310\lib\asyncio\runners.py", line 44, in run
    return loop.run_until_complete(main)
  File "C:\Users\Alwin Ang\AppData\Local\Programs\Python\Python310\lib\asyncio\base_events.py", line 633, in run_until_complete
    self.run_forever()
  File "C:\Users\Alwin Ang\AppData\Local\Programs\Python\Python310\lib\asyncio\windows_events.py", line 321, in run_forever
    super().run_forever()
  File "C:\Users\Alwin Ang\AppData\Local\Programs\Python\Python310\lib\asyncio\base_events.py", line 600, in run_forever
    self._run_once()
  File "C:\Users\Alwin Ang\AppData\Local\Programs\Python\Python310\lib\asyncio\base_events.py", line 1860, in _run_once
    event_list = self._selector.select(timeout)
  File "C:\Users\Alwin Ang\AppData\Local\Programs\Python\Python310\lib\asyncio\windows_events.py", line 439, in select
    self._poll(timeout)
  File "C:\Users\Alwin Ang\AppData\Local\Programs\Python\Python310\lib\asyncio\windows_events.py", line 788, in _poll
    status = _overlapped.GetQueuedCompletionStatus(self._iocp, ms)
KeyboardInterrupt

During handling of the above exception, another exception occurred:

Traceback (most recent call last):
  File "C:\Users\Alwin Ang\OneDrive - National University of Singapore\Y4S1\CG4002\CG4002_capstone\external_communications\Ultra96\main.py", line 39, in run
    await asyncio.gather(
asyncio.exceptions.CancelledError

During handling of the above exception, another exception occurred:

Traceback (most recent call last):
  File "C:\Users\Alwin Ang\OneDrive - National University of Singapore\Y4S1\CG4002\CG4002_capstone\external_communications\Ultra96\main.py", line 169, in main
    await ultra96.run()
  File "C:\Users\Alwin Ang\OneDrive - National University of Singapore\Y4S1\CG4002\CG4002_capstone\external_communications\Ultra96\main.py", line 49, in run
    await self.stop()
  File "C:\Users\Alwin Ang\OneDrive - National University of Singapore\Y4S1\CG4002\CG4002_capstone\external_communications\Ultra96\main.py", line 158, in stop
    await asyncio.gather(
  File "C:\Users\Alwin Ang\AppData\Local\Programs\Python\Python310\lib\asyncio\tasks.py", line 783, in gather
    fut = _ensure_future(arg, loop=loop)
  File "C:\Users\Alwin Ang\AppData\Local\Programs\Python\Python310\lib\asyncio\tasks.py", line 630, in _ensure_future
    raise TypeError('An asyncio.Future, a coroutine or an awaitable '
TypeError: An asyncio.Future, a coroutine or an awaitable is required
